{"url": "https://api.github.com/repos/pytorch/pytorch/issues/comments/384473774", "html_url": "https://github.com/pytorch/pytorch/issues/6937#issuecomment-384473774", "issue_url": "https://api.github.com/repos/pytorch/pytorch/issues/6937", "id": 384473774, "node_id": "MDEyOklzc3VlQ29tbWVudDM4NDQ3Mzc3NA==", "user": {"login": "wanganzhi", "id": 8628596, "node_id": "MDQ6VXNlcjg2Mjg1OTY=", "avatar_url": "https://avatars1.githubusercontent.com/u/8628596?v=4", "gravatar_id": "", "url": "https://api.github.com/users/wanganzhi", "html_url": "https://github.com/wanganzhi", "followers_url": "https://api.github.com/users/wanganzhi/followers", "following_url": "https://api.github.com/users/wanganzhi/following{/other_user}", "gists_url": "https://api.github.com/users/wanganzhi/gists{/gist_id}", "starred_url": "https://api.github.com/users/wanganzhi/starred{/owner}{/repo}", "subscriptions_url": "https://api.github.com/users/wanganzhi/subscriptions", "organizations_url": "https://api.github.com/users/wanganzhi/orgs", "repos_url": "https://api.github.com/users/wanganzhi/repos", "events_url": "https://api.github.com/users/wanganzhi/events{/privacy}", "received_events_url": "https://api.github.com/users/wanganzhi/received_events", "type": "User", "site_admin": false}, "created_at": "2018-04-26T00:22:46Z", "updated_at": "2018-04-26T00:22:46Z", "author_association": "NONE", "body_html": "<p>I met the same mistake too</p>", "body_text": "I met the same mistake too", "body": "I met the same mistake too"}