{"url": "https://api.github.com/repos/tensorflow/tensorflow/issues/comments/335452350", "html_url": "https://github.com/tensorflow/tensorflow/issues/13487#issuecomment-335452350", "issue_url": "https://api.github.com/repos/tensorflow/tensorflow/issues/13487", "id": 335452350, "node_id": "MDEyOklzc3VlQ29tbWVudDMzNTQ1MjM1MA==", "user": {"login": "vclteam", "id": 3509096, "node_id": "MDQ6VXNlcjM1MDkwOTY=", "avatar_url": "https://avatars1.githubusercontent.com/u/3509096?v=4", "gravatar_id": "", "url": "https://api.github.com/users/vclteam", "html_url": "https://github.com/vclteam", "followers_url": "https://api.github.com/users/vclteam/followers", "following_url": "https://api.github.com/users/vclteam/following{/other_user}", "gists_url": "https://api.github.com/users/vclteam/gists{/gist_id}", "starred_url": "https://api.github.com/users/vclteam/starred{/owner}{/repo}", "subscriptions_url": "https://api.github.com/users/vclteam/subscriptions", "organizations_url": "https://api.github.com/users/vclteam/orgs", "repos_url": "https://api.github.com/users/vclteam/repos", "events_url": "https://api.github.com/users/vclteam/events{/privacy}", "received_events_url": "https://api.github.com/users/vclteam/received_events", "type": "User", "site_admin": false}, "created_at": "2017-10-10T12:11:39Z", "updated_at": "2017-10-10T12:11:39Z", "author_association": "NONE", "body_html": "<p>and since i'm getting the same exception how exactly did u managed to overcome it?</p>", "body_text": "and since i'm getting the same exception how exactly did u managed to overcome it?", "body": "and since i'm getting the same exception how exactly did u managed to overcome it?\r\n\r\n\r\n"}