{"url": "https://api.github.com/repos/pytorch/pytorch/issues/5131", "repository_url": "https://api.github.com/repos/pytorch/pytorch", "labels_url": "https://api.github.com/repos/pytorch/pytorch/issues/5131/labels{/name}", "comments_url": "https://api.github.com/repos/pytorch/pytorch/issues/5131/comments", "events_url": "https://api.github.com/repos/pytorch/pytorch/issues/5131/events", "html_url": "https://github.com/pytorch/pytorch/issues/5131", "id": 295412869, "node_id": "MDU6SXNzdWUyOTU0MTI4Njk=", "number": 5131, "title": " 'SpatialDilatedConvolution' object has no attribute 'bias'", "user": {"login": "WayneZww", "id": 29515012, "node_id": "MDQ6VXNlcjI5NTE1MDEy", "avatar_url": "https://avatars0.githubusercontent.com/u/29515012?v=4", "gravatar_id": "", "url": "https://api.github.com/users/WayneZww", "html_url": "https://github.com/WayneZww", "followers_url": "https://api.github.com/users/WayneZww/followers", "following_url": "https://api.github.com/users/WayneZww/following{/other_user}", "gists_url": "https://api.github.com/users/WayneZww/gists{/gist_id}", "starred_url": "https://api.github.com/users/WayneZww/starred{/owner}{/repo}", "subscriptions_url": "https://api.github.com/users/WayneZww/subscriptions", "organizations_url": "https://api.github.com/users/WayneZww/orgs", "repos_url": "https://api.github.com/users/WayneZww/repos", "events_url": "https://api.github.com/users/WayneZww/events{/privacy}", "received_events_url": "https://api.github.com/users/WayneZww/received_events", "type": "User", "site_admin": false}, "labels": [], "state": "open", "locked": false, "assignee": null, "assignees": [], "milestone": null, "comments": 0, "created_at": "2018-02-08T07:41:01Z", "updated_at": "2018-02-08T07:41:59Z", "closed_at": null, "author_association": "NONE", "body_html": "<ul>\n<li>OS:Ubuntu 14.04</li>\n<li>PyTorch version: 0.3.0 post4</li>\n<li>How you installed PyTorch (conda, pip, source):pip</li>\n<li>Python version:2.7<br>\nAfter trying load a torch model, I want to print it ,then got the error</li>\n</ul>\n<pre><code>AttributeError                            Traceback (most recent call last)\n&lt;ipython-input-7-02c7391dff0e&gt; in &lt;module&gt;()\n----&gt; 3 print(model)\n\n/home/.virtualenvs/dl-py2/lib/python2.7/site-packages/torch/legacy/nn/Sequential.pyc in __repr__(self)\n     81         res = res + next + 'output]'\n     82         for i in range(len(self.modules)):\n---&gt; 83             res = res + line + tab + '(' + str(i) + '): ' + str(self.modules[i]).replace(line, line + tab)\n     84 \n     85         res = res + line + '}'\n\n/home/.virtualenvs/dl-py2/lib/python2.7/site-packages/torch/legacy/nn/SpatialDilatedConvolution.pyc in __repr__(self)\n     84 \n     85         s += ')'\n---&gt; 86         if self.bias is None:\n     87             s += ' without bias'\n     88         return s\n\nAttributeError: 'SpatialDilatedConvolution' object has no attribute 'bias'\n</code></pre>\n<p>Since I know I have this layer in my t7 model, but I do not know why I meet with this. could someone can fix this?</p>", "body_text": "OS:Ubuntu 14.04\nPyTorch version: 0.3.0 post4\nHow you installed PyTorch (conda, pip, source):pip\nPython version:2.7\nAfter trying load a torch model, I want to print it ,then got the error\n\nAttributeError                            Traceback (most recent call last)\n<ipython-input-7-02c7391dff0e> in <module>()\n----> 3 print(model)\n\n/home/.virtualenvs/dl-py2/lib/python2.7/site-packages/torch/legacy/nn/Sequential.pyc in __repr__(self)\n     81         res = res + next + 'output]'\n     82         for i in range(len(self.modules)):\n---> 83             res = res + line + tab + '(' + str(i) + '): ' + str(self.modules[i]).replace(line, line + tab)\n     84 \n     85         res = res + line + '}'\n\n/home/.virtualenvs/dl-py2/lib/python2.7/site-packages/torch/legacy/nn/SpatialDilatedConvolution.pyc in __repr__(self)\n     84 \n     85         s += ')'\n---> 86         if self.bias is None:\n     87             s += ' without bias'\n     88         return s\n\nAttributeError: 'SpatialDilatedConvolution' object has no attribute 'bias'\n\nSince I know I have this layer in my t7 model, but I do not know why I meet with this. could someone can fix this?", "body": "- OS:Ubuntu 14.04\r\n- PyTorch version: 0.3.0 post4\r\n- How you installed PyTorch (conda, pip, source):pip\r\n- Python version:2.7\r\nAfter trying load a torch model, I want to print it ,then got the error\r\n```\r\nAttributeError                            Traceback (most recent call last)\r\n<ipython-input-7-02c7391dff0e> in <module>()\r\n----> 3 print(model)\r\n\r\n/home/.virtualenvs/dl-py2/lib/python2.7/site-packages/torch/legacy/nn/Sequential.pyc in __repr__(self)\r\n     81         res = res + next + 'output]'\r\n     82         for i in range(len(self.modules)):\r\n---> 83             res = res + line + tab + '(' + str(i) + '): ' + str(self.modules[i]).replace(line, line + tab)\r\n     84 \r\n     85         res = res + line + '}'\r\n\r\n/home/.virtualenvs/dl-py2/lib/python2.7/site-packages/torch/legacy/nn/SpatialDilatedConvolution.pyc in __repr__(self)\r\n     84 \r\n     85         s += ')'\r\n---> 86         if self.bias is None:\r\n     87             s += ' without bias'\r\n     88         return s\r\n\r\nAttributeError: 'SpatialDilatedConvolution' object has no attribute 'bias'\r\n```\r\nSince I know I have this layer in my t7 model, but I do not know why I meet with this. could someone can fix this?\r\n\r\n"}