{"url": "https://api.github.com/repos/tensorflow/tensorflow/issues/comments/385585077", "html_url": "https://github.com/tensorflow/tensorflow/issues/17945#issuecomment-385585077", "issue_url": "https://api.github.com/repos/tensorflow/tensorflow/issues/17945", "id": 385585077, "node_id": "MDEyOklzc3VlQ29tbWVudDM4NTU4NTA3Nw==", "user": {"login": "cczhong11", "id": 7358252, "node_id": "MDQ6VXNlcjczNTgyNTI=", "avatar_url": "https://avatars3.githubusercontent.com/u/7358252?v=4", "gravatar_id": "", "url": "https://api.github.com/users/cczhong11", "html_url": "https://github.com/cczhong11", "followers_url": "https://api.github.com/users/cczhong11/followers", "following_url": "https://api.github.com/users/cczhong11/following{/other_user}", "gists_url": "https://api.github.com/users/cczhong11/gists{/gist_id}", "starred_url": "https://api.github.com/users/cczhong11/starred{/owner}{/repo}", "subscriptions_url": "https://api.github.com/users/cczhong11/subscriptions", "organizations_url": "https://api.github.com/users/cczhong11/orgs", "repos_url": "https://api.github.com/users/cczhong11/repos", "events_url": "https://api.github.com/users/cczhong11/events{/privacy}", "received_events_url": "https://api.github.com/users/cczhong11/received_events", "type": "User", "site_admin": false}, "created_at": "2018-05-01T02:34:41Z", "updated_at": "2018-05-01T02:34:41Z", "author_association": "NONE", "body_html": "<p><a href=\"https://gist.github.com/cczhong11/b3ee85d81d9d07e6c47f4a1ec49c66e8\">https://gist.github.com/cczhong11/b3ee85d81d9d07e6c47f4a1ec49c66e8</a></p>\n<p>This code could get this problem. The dataset could get from the url in the code. I listed all the packages installed by Anaconda. It is a interesting bug. I could only reproduce this when I first installed tensorflow. You could use the following code to install packages on a new virtual machine.</p>\n<pre><code>wget http://repo.continuum.io/miniconda/Miniconda3-4.4.10-Linux-x86_64.sh -O ~/miniconda.sh\nbash ~/miniconda.sh -b -p $HOME/miniconda\nexport PATH=\"$HOME/miniconda/bin:$PATH\"\nsource $HOME/miniconda/bin/activate\nconda install tensorflow keras -y\n</code></pre>\n<p>After I tried to install the 1.5.0 tensorflow and installed 1.7.0 tensorflow again, I could not reproduce this error.</p>", "body_text": "https://gist.github.com/cczhong11/b3ee85d81d9d07e6c47f4a1ec49c66e8\nThis code could get this problem. The dataset could get from the url in the code. I listed all the packages installed by Anaconda. It is a interesting bug. I could only reproduce this when I first installed tensorflow. You could use the following code to install packages on a new virtual machine.\nwget http://repo.continuum.io/miniconda/Miniconda3-4.4.10-Linux-x86_64.sh -O ~/miniconda.sh\nbash ~/miniconda.sh -b -p $HOME/miniconda\nexport PATH=\"$HOME/miniconda/bin:$PATH\"\nsource $HOME/miniconda/bin/activate\nconda install tensorflow keras -y\n\nAfter I tried to install the 1.5.0 tensorflow and installed 1.7.0 tensorflow again, I could not reproduce this error.", "body": "https://gist.github.com/cczhong11/b3ee85d81d9d07e6c47f4a1ec49c66e8\r\n\r\nThis code could get this problem. The dataset could get from the url in the code. I listed all the packages installed by Anaconda. It is a interesting bug. I could only reproduce this when I first installed tensorflow. You could use the following code to install packages on a new virtual machine.\r\n```\r\nwget http://repo.continuum.io/miniconda/Miniconda3-4.4.10-Linux-x86_64.sh -O ~/miniconda.sh\r\nbash ~/miniconda.sh -b -p $HOME/miniconda\r\nexport PATH=\"$HOME/miniconda/bin:$PATH\"\r\nsource $HOME/miniconda/bin/activate\r\nconda install tensorflow keras -y\r\n```\r\n\r\n\r\nAfter I tried to install the 1.5.0 tensorflow and installed 1.7.0 tensorflow again, I could not reproduce this error."}