{"url": "https://api.github.com/repos/tensorflow/tensorflow/issues/22064", "repository_url": "https://api.github.com/repos/tensorflow/tensorflow", "labels_url": "https://api.github.com/repos/tensorflow/tensorflow/issues/22064/labels{/name}", "comments_url": "https://api.github.com/repos/tensorflow/tensorflow/issues/22064/comments", "events_url": "https://api.github.com/repos/tensorflow/tensorflow/issues/22064/events", "html_url": "https://github.com/tensorflow/tensorflow/issues/22064", "id": 356967139, "node_id": "MDU6SXNzdWUzNTY5NjcxMzk=", "number": 22064, "title": "Can't save models trained with tf.contrib.cudnn_rnn.CudnnRNNRelu", "user": {"login": "thomasquintana", "id": 1891840, "node_id": "MDQ6VXNlcjE4OTE4NDA=", "avatar_url": "https://avatars3.githubusercontent.com/u/1891840?v=4", "gravatar_id": "", "url": "https://api.github.com/users/thomasquintana", "html_url": "https://github.com/thomasquintana", "followers_url": "https://api.github.com/users/thomasquintana/followers", "following_url": "https://api.github.com/users/thomasquintana/following{/other_user}", "gists_url": "https://api.github.com/users/thomasquintana/gists{/gist_id}", "starred_url": "https://api.github.com/users/thomasquintana/starred{/owner}{/repo}", "subscriptions_url": "https://api.github.com/users/thomasquintana/subscriptions", "organizations_url": "https://api.github.com/users/thomasquintana/orgs", "repos_url": "https://api.github.com/users/thomasquintana/repos", "events_url": "https://api.github.com/users/thomasquintana/events{/privacy}", "received_events_url": "https://api.github.com/users/thomasquintana/received_events", "type": "User", "site_admin": false}, "labels": [], "state": "closed", "locked": false, "assignee": {"login": "shivaniag", "id": 16565716, "node_id": "MDQ6VXNlcjE2NTY1NzE2", "avatar_url": "https://avatars1.githubusercontent.com/u/16565716?v=4", "gravatar_id": "", "url": "https://api.github.com/users/shivaniag", "html_url": "https://github.com/shivaniag", "followers_url": "https://api.github.com/users/shivaniag/followers", "following_url": "https://api.github.com/users/shivaniag/following{/other_user}", "gists_url": "https://api.github.com/users/shivaniag/gists{/gist_id}", "starred_url": "https://api.github.com/users/shivaniag/starred{/owner}{/repo}", "subscriptions_url": "https://api.github.com/users/shivaniag/subscriptions", "organizations_url": "https://api.github.com/users/shivaniag/orgs", "repos_url": "https://api.github.com/users/shivaniag/repos", "events_url": "https://api.github.com/users/shivaniag/events{/privacy}", "received_events_url": "https://api.github.com/users/shivaniag/received_events", "type": "User", "site_admin": false}, "assignees": [{"login": "shivaniag", "id": 16565716, "node_id": "MDQ6VXNlcjE2NTY1NzE2", "avatar_url": "https://avatars1.githubusercontent.com/u/16565716?v=4", "gravatar_id": "", "url": "https://api.github.com/users/shivaniag", "html_url": "https://github.com/shivaniag", "followers_url": "https://api.github.com/users/shivaniag/followers", "following_url": "https://api.github.com/users/shivaniag/following{/other_user}", "gists_url": "https://api.github.com/users/shivaniag/gists{/gist_id}", "starred_url": "https://api.github.com/users/shivaniag/starred{/owner}{/repo}", "subscriptions_url": "https://api.github.com/users/shivaniag/subscriptions", "organizations_url": "https://api.github.com/users/shivaniag/orgs", "repos_url": "https://api.github.com/users/shivaniag/repos", "events_url": "https://api.github.com/users/shivaniag/events{/privacy}", "received_events_url": "https://api.github.com/users/shivaniag/received_events", "type": "User", "site_admin": false}], "milestone": null, "comments": 1, "created_at": "2018-09-04T20:37:55Z", "updated_at": "2018-09-09T13:00:11Z", "closed_at": "2018-09-09T13:00:11Z", "author_association": "NONE", "body_html": "<p>Please go to Stack Overflow for help and support:</p>\n<p><a href=\"https://stackoverflow.com/questions/tagged/tensorflow\" rel=\"nofollow\">https://stackoverflow.com/questions/tagged/tensorflow</a></p>\n<p>If you open a GitHub issue, here is our policy:</p>\n<ol>\n<li>It must be a bug, a feature request, or a significant problem with documentation (for small docs fixes please send a PR instead).</li>\n<li>The form below must be filled out.</li>\n<li>It shouldn't be a TensorBoard issue. Those go <a href=\"https://github.com/tensorflow/tensorboard/issues\">here</a>.</li>\n</ol>\n<p><strong>Here's why we have that policy</strong>: TensorFlow developers respond to issues. We want to focus on work that benefits the whole community, e.g., fixing bugs and adding features. Support only helps individuals. GitHub also notifies thousands of people when issues are filed. We want them to see you communicating an interesting problem, rather than being redirected to Stack Overflow.</p>\n<hr>\n<h3>System information</h3>\n<ul>\n<li><strong>Have I written custom code (as opposed to using a stock example script provided in TensorFlow)</strong>: Yes</li>\n<li><strong>OS Platform and Distribution (e.g., Linux Ubuntu 16.04)</strong>: Linux Ubuntu 16.04</li>\n<li><strong>Mobile device (e.g. iPhone 8, Pixel 2, Samsung Galaxy) if the issue happens on mobile device</strong>: N/A</li>\n<li><strong>TensorFlow installed from (source or binary)</strong>: binary</li>\n<li><strong>TensorFlow version (use command below)</strong>: 1.10.1</li>\n<li><strong>Python version</strong>: 3.5.2</li>\n<li><strong>Bazel version (if compiling from source)</strong>: N/A</li>\n<li><strong>GCC/Compiler version (if compiling from source)</strong>: N/A</li>\n<li><strong>CUDA/cuDNN version</strong>: 9.0/7.0.3.11</li>\n<li><strong>GPU model and memory</strong>: Quadro M1200</li>\n<li><strong>Exact command to reproduce</strong>:</li>\n</ul>\n<p>You can collect some of this information using our environment capture script:</p>\n<p><a href=\"https://github.com/tensorflow/tensorflow/tree/master/tools/tf_env_collect.sh\">https://github.com/tensorflow/tensorflow/tree/master/tools/tf_env_collect.sh</a></p>\n<p>You can obtain the TensorFlow version with</p>\n<p>python -c \"import tensorflow as tf; print(tf.GIT_VERSION, tf.VERSION)\"</p>\n<h3>Describe the problem</h3>\n<p>Describe the problem clearly here. Be sure to convey here why it's a bug in TensorFlow or a feature request.</p>\n<p>When I try to create a saver for a session with a graph containing a module from the <code>tf.contrib.cudnn_rnn</code> package I get <code>AttributeError: 'Tensor' object has no attribute 'assign'</code></p>\n<h3>Source code / logs</h3>\n<p>Include any logs or source code that would be helpful to diagnose the problem. If including tracebacks, please include the full traceback. Large logs and files should be attached. Try to provide a reproducible test case that is the bare minimum necessary to generate the problem.</p>\n<pre><code>Traceback (most recent call last):\n  File \"train.py\", line 154, in &lt;module&gt;\n    update_interval=config['training']['update_interval'])\n  File \"train.py\", line 66, in train\n    saver = tf.train.Saver()\n  File \"/usr/local/lib/python3.5/dist-packages/tensorflow/python/training/saver.py\", line 1281, in __init__\n    self.build()\n  File \"/usr/local/lib/python3.5/dist-packages/tensorflow/python/training/saver.py\", line 1293, in build\n    self._build(self._filename, build_save=True, build_restore=True)\n  File \"/usr/local/lib/python3.5/dist-packages/tensorflow/python/training/saver.py\", line 1330, in _build\n    build_save=build_save, build_restore=build_restore)\n  File \"/usr/local/lib/python3.5/dist-packages/tensorflow/python/training/saver.py\", line 778, in _build_internal\n    restore_sequentially, reshape)\n  File \"/usr/local/lib/python3.5/dist-packages/tensorflow/python/training/saver.py\", line 419, in _AddRestoreOps\n    assign_ops.append(saveable.restore(saveable_tensors, shapes))\n  File \"/usr/local/lib/python3.5/dist-packages/tensorflow/contrib/cudnn_rnn/python/ops/cudnn_rnn_ops.py\", line 291, in restore\n    self._variables, opaque_params, validate_shape=False)\n  File \"/usr/local/lib/python3.5/dist-packages/tensorflow/python/ops/state_ops.py\", line 217, in assign\n    return ref.assign(value, name=name)\nAttributeError: 'Tensor' object has no attribute 'assign'\n</code></pre>", "body_text": "Please go to Stack Overflow for help and support:\nhttps://stackoverflow.com/questions/tagged/tensorflow\nIf you open a GitHub issue, here is our policy:\n\nIt must be a bug, a feature request, or a significant problem with documentation (for small docs fixes please send a PR instead).\nThe form below must be filled out.\nIt shouldn't be a TensorBoard issue. Those go here.\n\nHere's why we have that policy: TensorFlow developers respond to issues. We want to focus on work that benefits the whole community, e.g., fixing bugs and adding features. Support only helps individuals. GitHub also notifies thousands of people when issues are filed. We want them to see you communicating an interesting problem, rather than being redirected to Stack Overflow.\n\nSystem information\n\nHave I written custom code (as opposed to using a stock example script provided in TensorFlow): Yes\nOS Platform and Distribution (e.g., Linux Ubuntu 16.04): Linux Ubuntu 16.04\nMobile device (e.g. iPhone 8, Pixel 2, Samsung Galaxy) if the issue happens on mobile device: N/A\nTensorFlow installed from (source or binary): binary\nTensorFlow version (use command below): 1.10.1\nPython version: 3.5.2\nBazel version (if compiling from source): N/A\nGCC/Compiler version (if compiling from source): N/A\nCUDA/cuDNN version: 9.0/7.0.3.11\nGPU model and memory: Quadro M1200\nExact command to reproduce:\n\nYou can collect some of this information using our environment capture script:\nhttps://github.com/tensorflow/tensorflow/tree/master/tools/tf_env_collect.sh\nYou can obtain the TensorFlow version with\npython -c \"import tensorflow as tf; print(tf.GIT_VERSION, tf.VERSION)\"\nDescribe the problem\nDescribe the problem clearly here. Be sure to convey here why it's a bug in TensorFlow or a feature request.\nWhen I try to create a saver for a session with a graph containing a module from the tf.contrib.cudnn_rnn package I get AttributeError: 'Tensor' object has no attribute 'assign'\nSource code / logs\nInclude any logs or source code that would be helpful to diagnose the problem. If including tracebacks, please include the full traceback. Large logs and files should be attached. Try to provide a reproducible test case that is the bare minimum necessary to generate the problem.\nTraceback (most recent call last):\n  File \"train.py\", line 154, in <module>\n    update_interval=config['training']['update_interval'])\n  File \"train.py\", line 66, in train\n    saver = tf.train.Saver()\n  File \"/usr/local/lib/python3.5/dist-packages/tensorflow/python/training/saver.py\", line 1281, in __init__\n    self.build()\n  File \"/usr/local/lib/python3.5/dist-packages/tensorflow/python/training/saver.py\", line 1293, in build\n    self._build(self._filename, build_save=True, build_restore=True)\n  File \"/usr/local/lib/python3.5/dist-packages/tensorflow/python/training/saver.py\", line 1330, in _build\n    build_save=build_save, build_restore=build_restore)\n  File \"/usr/local/lib/python3.5/dist-packages/tensorflow/python/training/saver.py\", line 778, in _build_internal\n    restore_sequentially, reshape)\n  File \"/usr/local/lib/python3.5/dist-packages/tensorflow/python/training/saver.py\", line 419, in _AddRestoreOps\n    assign_ops.append(saveable.restore(saveable_tensors, shapes))\n  File \"/usr/local/lib/python3.5/dist-packages/tensorflow/contrib/cudnn_rnn/python/ops/cudnn_rnn_ops.py\", line 291, in restore\n    self._variables, opaque_params, validate_shape=False)\n  File \"/usr/local/lib/python3.5/dist-packages/tensorflow/python/ops/state_ops.py\", line 217, in assign\n    return ref.assign(value, name=name)\nAttributeError: 'Tensor' object has no attribute 'assign'", "body": "Please go to Stack Overflow for help and support:\r\n\r\nhttps://stackoverflow.com/questions/tagged/tensorflow\r\n\r\nIf you open a GitHub issue, here is our policy:\r\n\r\n1. It must be a bug, a feature request, or a significant problem with documentation (for small docs fixes please send a PR instead).\r\n2. The form below must be filled out.\r\n3. It shouldn't be a TensorBoard issue. Those go [here](https://github.com/tensorflow/tensorboard/issues).\r\n\r\n**Here's why we have that policy**: TensorFlow developers respond to issues. We want to focus on work that benefits the whole community, e.g., fixing bugs and adding features. Support only helps individuals. GitHub also notifies thousands of people when issues are filed. We want them to see you communicating an interesting problem, rather than being redirected to Stack Overflow.\r\n\r\n------------------------\r\n\r\n### System information\r\n- **Have I written custom code (as opposed to using a stock example script provided in TensorFlow)**: Yes\r\n- **OS Platform and Distribution (e.g., Linux Ubuntu 16.04)**: Linux Ubuntu 16.04\r\n- **Mobile device (e.g. iPhone 8, Pixel 2, Samsung Galaxy) if the issue happens on mobile device**: N/A\r\n- **TensorFlow installed from (source or binary)**: binary\r\n- **TensorFlow version (use command below)**: 1.10.1\r\n- **Python version**: 3.5.2\r\n- **Bazel version (if compiling from source)**: N/A\r\n- **GCC/Compiler version (if compiling from source)**: N/A\r\n- **CUDA/cuDNN version**: 9.0/7.0.3.11\r\n- **GPU model and memory**: Quadro M1200\r\n- **Exact command to reproduce**:\r\n\r\nYou can collect some of this information using our environment capture script:\r\n\r\nhttps://github.com/tensorflow/tensorflow/tree/master/tools/tf_env_collect.sh\r\n\r\nYou can obtain the TensorFlow version with\r\n\r\npython -c \"import tensorflow as tf; print(tf.GIT_VERSION, tf.VERSION)\"\r\n\r\n### Describe the problem\r\nDescribe the problem clearly here. Be sure to convey here why it's a bug in TensorFlow or a feature request.\r\n\r\nWhen I try to create a saver for a session with a graph containing a module from the `tf.contrib.cudnn_rnn` package I get `AttributeError: 'Tensor' object has no attribute 'assign'`\r\n\r\n### Source code / logs\r\nInclude any logs or source code that would be helpful to diagnose the problem. If including tracebacks, please include the full traceback. Large logs and files should be attached. Try to provide a reproducible test case that is the bare minimum necessary to generate the problem.\r\n\r\n```\r\nTraceback (most recent call last):\r\n  File \"train.py\", line 154, in <module>\r\n    update_interval=config['training']['update_interval'])\r\n  File \"train.py\", line 66, in train\r\n    saver = tf.train.Saver()\r\n  File \"/usr/local/lib/python3.5/dist-packages/tensorflow/python/training/saver.py\", line 1281, in __init__\r\n    self.build()\r\n  File \"/usr/local/lib/python3.5/dist-packages/tensorflow/python/training/saver.py\", line 1293, in build\r\n    self._build(self._filename, build_save=True, build_restore=True)\r\n  File \"/usr/local/lib/python3.5/dist-packages/tensorflow/python/training/saver.py\", line 1330, in _build\r\n    build_save=build_save, build_restore=build_restore)\r\n  File \"/usr/local/lib/python3.5/dist-packages/tensorflow/python/training/saver.py\", line 778, in _build_internal\r\n    restore_sequentially, reshape)\r\n  File \"/usr/local/lib/python3.5/dist-packages/tensorflow/python/training/saver.py\", line 419, in _AddRestoreOps\r\n    assign_ops.append(saveable.restore(saveable_tensors, shapes))\r\n  File \"/usr/local/lib/python3.5/dist-packages/tensorflow/contrib/cudnn_rnn/python/ops/cudnn_rnn_ops.py\", line 291, in restore\r\n    self._variables, opaque_params, validate_shape=False)\r\n  File \"/usr/local/lib/python3.5/dist-packages/tensorflow/python/ops/state_ops.py\", line 217, in assign\r\n    return ref.assign(value, name=name)\r\nAttributeError: 'Tensor' object has no attribute 'assign'\r\n```\r\n"}