{"url": "https://api.github.com/repos/tensorflow/tensorflow/issues/comments/393721197", "html_url": "https://github.com/tensorflow/tensorflow/pull/19675#issuecomment-393721197", "issue_url": "https://api.github.com/repos/tensorflow/tensorflow/issues/19675", "id": 393721197, "node_id": "MDEyOklzc3VlQ29tbWVudDM5MzcyMTE5Nw==", "user": {"login": "case540", "id": 1299636, "node_id": "MDQ6VXNlcjEyOTk2MzY=", "avatar_url": "https://avatars2.githubusercontent.com/u/1299636?v=4", "gravatar_id": "", "url": "https://api.github.com/users/case540", "html_url": "https://github.com/case540", "followers_url": "https://api.github.com/users/case540/followers", "following_url": "https://api.github.com/users/case540/following{/other_user}", "gists_url": "https://api.github.com/users/case540/gists{/gist_id}", "starred_url": "https://api.github.com/users/case540/starred{/owner}{/repo}", "subscriptions_url": "https://api.github.com/users/case540/subscriptions", "organizations_url": "https://api.github.com/users/case540/orgs", "repos_url": "https://api.github.com/users/case540/repos", "events_url": "https://api.github.com/users/case540/events{/privacy}", "received_events_url": "https://api.github.com/users/case540/received_events", "type": "User", "site_admin": false}, "created_at": "2018-06-01T00:15:04Z", "updated_at": "2018-06-01T00:15:04Z", "author_association": "MEMBER", "body_html": "<p>Is there a fix internally that creating a new push would solve? Otherwise, I'm keeping on trying things to fix this. Also, not sure if there is an easy way to run the pip3 tests locally. Do you know a way <a class=\"user-mention\" data-hovercard-type=\"user\" data-hovercard-url=\"/hovercards?user_id=5588272\" data-octo-click=\"hovercard-link-click\" data-octo-dimensions=\"link_type:self\" href=\"https://github.com/av8ramit\">@av8ramit</a></p>", "body_text": "Is there a fix internally that creating a new push would solve? Otherwise, I'm keeping on trying things to fix this. Also, not sure if there is an easy way to run the pip3 tests locally. Do you know a way @av8ramit", "body": "Is there a fix internally that creating a new push would solve? Otherwise, I'm keeping on trying things to fix this. Also, not sure if there is an easy way to run the pip3 tests locally. Do you know a way @av8ramit "}