{"url": "https://api.github.com/repos/tensorflow/tensorflow/issues/22091", "repository_url": "https://api.github.com/repos/tensorflow/tensorflow", "labels_url": "https://api.github.com/repos/tensorflow/tensorflow/issues/22091/labels{/name}", "comments_url": "https://api.github.com/repos/tensorflow/tensorflow/issues/22091/comments", "events_url": "https://api.github.com/repos/tensorflow/tensorflow/issues/22091/events", "html_url": "https://github.com/tensorflow/tensorflow/issues/22091", "id": 357205618, "node_id": "MDU6SXNzdWUzNTcyMDU2MTg=", "number": 22091, "title": "Failed to load the native TensorFlow runtime.", "user": {"login": "AashishGit", "id": 29608530, "node_id": "MDQ6VXNlcjI5NjA4NTMw", "avatar_url": "https://avatars1.githubusercontent.com/u/29608530?v=4", "gravatar_id": "", "url": "https://api.github.com/users/AashishGit", "html_url": "https://github.com/AashishGit", "followers_url": "https://api.github.com/users/AashishGit/followers", "following_url": "https://api.github.com/users/AashishGit/following{/other_user}", "gists_url": "https://api.github.com/users/AashishGit/gists{/gist_id}", "starred_url": "https://api.github.com/users/AashishGit/starred{/owner}{/repo}", "subscriptions_url": "https://api.github.com/users/AashishGit/subscriptions", "organizations_url": "https://api.github.com/users/AashishGit/orgs", "repos_url": "https://api.github.com/users/AashishGit/repos", "events_url": "https://api.github.com/users/AashishGit/events{/privacy}", "received_events_url": "https://api.github.com/users/AashishGit/received_events", "type": "User", "site_admin": false}, "labels": [{"id": 386191887, "node_id": "MDU6TGFiZWwzODYxOTE4ODc=", "url": "https://api.github.com/repos/tensorflow/tensorflow/labels/stat:awaiting%20response", "name": "stat:awaiting response", "color": "f4b400", "default": false}], "state": "closed", "locked": false, "assignee": {"login": "asimshankar", "id": 16018, "node_id": "MDQ6VXNlcjE2MDE4", "avatar_url": "https://avatars2.githubusercontent.com/u/16018?v=4", "gravatar_id": "", "url": "https://api.github.com/users/asimshankar", "html_url": "https://github.com/asimshankar", "followers_url": "https://api.github.com/users/asimshankar/followers", "following_url": "https://api.github.com/users/asimshankar/following{/other_user}", "gists_url": "https://api.github.com/users/asimshankar/gists{/gist_id}", "starred_url": "https://api.github.com/users/asimshankar/starred{/owner}{/repo}", "subscriptions_url": "https://api.github.com/users/asimshankar/subscriptions", "organizations_url": "https://api.github.com/users/asimshankar/orgs", "repos_url": "https://api.github.com/users/asimshankar/repos", "events_url": "https://api.github.com/users/asimshankar/events{/privacy}", "received_events_url": "https://api.github.com/users/asimshankar/received_events", "type": "User", "site_admin": false}, "assignees": [{"login": "asimshankar", "id": 16018, "node_id": "MDQ6VXNlcjE2MDE4", "avatar_url": "https://avatars2.githubusercontent.com/u/16018?v=4", "gravatar_id": "", "url": "https://api.github.com/users/asimshankar", "html_url": "https://github.com/asimshankar", "followers_url": "https://api.github.com/users/asimshankar/followers", "following_url": "https://api.github.com/users/asimshankar/following{/other_user}", "gists_url": "https://api.github.com/users/asimshankar/gists{/gist_id}", "starred_url": "https://api.github.com/users/asimshankar/starred{/owner}{/repo}", "subscriptions_url": "https://api.github.com/users/asimshankar/subscriptions", "organizations_url": "https://api.github.com/users/asimshankar/orgs", "repos_url": "https://api.github.com/users/asimshankar/repos", "events_url": "https://api.github.com/users/asimshankar/events{/privacy}", "received_events_url": "https://api.github.com/users/asimshankar/received_events", "type": "User", "site_admin": false}], "milestone": null, "comments": 4, "created_at": "2018-09-05T12:28:21Z", "updated_at": "2018-10-31T18:20:19Z", "closed_at": "2018-10-31T18:20:18Z", "author_association": "NONE", "body_html": "<p>Traceback (most recent call last):<br>\nFile \"test_pixel_link.py\", line 5, in <br>\nimport tensorflow as tf<br>\nFile \"/home/aashish/anaconda3/envs/pixel_link/lib/python2.7/site-packages/tensorflow/<strong>init</strong>.py\", line 24, in <br>\nfrom tensorflow.python import *<br>\nFile \"/home/aashish/anaconda3/envs/pixel_link/lib/python2.7/site-packages/tensorflow/python/<strong>init</strong>.py\", line 51, in <br>\nfrom tensorflow.python import pywrap_tensorflow<br>\nFile \"/home/aashish/anaconda3/envs/pixel_link/lib/python2.7/site-packages/tensorflow/python/pywrap_tensorflow.py\", line 52, in <br>\nraise ImportError(msg)<br>\nImportError: Traceback (most recent call last):<br>\nFile \"/home/aashish/anaconda3/envs/pixel_link/lib/python2.7/site-packages/tensorflow/python/pywrap_tensorflow.py\", line 41, in <br>\nfrom tensorflow.python.pywrap_tensorflow_internal import *<br>\nFile \"/home/aashish/anaconda3/envs/pixel_link/lib/python2.7/site-packages/tensorflow/python/pywrap_tensorflow_internal.py\", line 28, in <br>\n_pywrap_tensorflow_internal = swig_import_helper()<br>\nFile \"/home/aashish/anaconda3/envs/pixel_link/lib/python2.7/site-packages/tensorflow/python/pywrap_tensorflow_internal.py\", line 24, in swig_import_helper<br>\n_mod = imp.load_module('_pywrap_tensorflow_internal', fp, pathname, description)<br>\nImportError: libcuda.so.1: cannot open shared object file: No such file or directory</p>\n<p>Failed to load the native TensorFlow runtime.</p>\n<p>See <a href=\"https://www.tensorflow.org/install/install_sources#common_installation_problems\" rel=\"nofollow\">https://www.tensorflow.org/install/install_sources#common_installation_problems</a></p>\n<p>for some common reasons and solutions.  Include the entire stack trace<br>\nabove this error message when asking for help.</p>", "body_text": "Traceback (most recent call last):\nFile \"test_pixel_link.py\", line 5, in \nimport tensorflow as tf\nFile \"/home/aashish/anaconda3/envs/pixel_link/lib/python2.7/site-packages/tensorflow/init.py\", line 24, in \nfrom tensorflow.python import *\nFile \"/home/aashish/anaconda3/envs/pixel_link/lib/python2.7/site-packages/tensorflow/python/init.py\", line 51, in \nfrom tensorflow.python import pywrap_tensorflow\nFile \"/home/aashish/anaconda3/envs/pixel_link/lib/python2.7/site-packages/tensorflow/python/pywrap_tensorflow.py\", line 52, in \nraise ImportError(msg)\nImportError: Traceback (most recent call last):\nFile \"/home/aashish/anaconda3/envs/pixel_link/lib/python2.7/site-packages/tensorflow/python/pywrap_tensorflow.py\", line 41, in \nfrom tensorflow.python.pywrap_tensorflow_internal import *\nFile \"/home/aashish/anaconda3/envs/pixel_link/lib/python2.7/site-packages/tensorflow/python/pywrap_tensorflow_internal.py\", line 28, in \n_pywrap_tensorflow_internal = swig_import_helper()\nFile \"/home/aashish/anaconda3/envs/pixel_link/lib/python2.7/site-packages/tensorflow/python/pywrap_tensorflow_internal.py\", line 24, in swig_import_helper\n_mod = imp.load_module('_pywrap_tensorflow_internal', fp, pathname, description)\nImportError: libcuda.so.1: cannot open shared object file: No such file or directory\nFailed to load the native TensorFlow runtime.\nSee https://www.tensorflow.org/install/install_sources#common_installation_problems\nfor some common reasons and solutions.  Include the entire stack trace\nabove this error message when asking for help.", "body": "Traceback (most recent call last):\r\n  File \"test_pixel_link.py\", line 5, in <module>\r\n    import tensorflow as tf\r\n  File \"/home/aashish/anaconda3/envs/pixel_link/lib/python2.7/site-packages/tensorflow/__init__.py\", line 24, in <module>\r\n    from tensorflow.python import *\r\n  File \"/home/aashish/anaconda3/envs/pixel_link/lib/python2.7/site-packages/tensorflow/python/__init__.py\", line 51, in <module>\r\n    from tensorflow.python import pywrap_tensorflow\r\n  File \"/home/aashish/anaconda3/envs/pixel_link/lib/python2.7/site-packages/tensorflow/python/pywrap_tensorflow.py\", line 52, in <module>\r\n    raise ImportError(msg)\r\nImportError: Traceback (most recent call last):\r\n  File \"/home/aashish/anaconda3/envs/pixel_link/lib/python2.7/site-packages/tensorflow/python/pywrap_tensorflow.py\", line 41, in <module>\r\n    from tensorflow.python.pywrap_tensorflow_internal import *\r\n  File \"/home/aashish/anaconda3/envs/pixel_link/lib/python2.7/site-packages/tensorflow/python/pywrap_tensorflow_internal.py\", line 28, in <module>\r\n    _pywrap_tensorflow_internal = swig_import_helper()\r\n  File \"/home/aashish/anaconda3/envs/pixel_link/lib/python2.7/site-packages/tensorflow/python/pywrap_tensorflow_internal.py\", line 24, in swig_import_helper\r\n    _mod = imp.load_module('_pywrap_tensorflow_internal', fp, pathname, description)\r\nImportError: libcuda.so.1: cannot open shared object file: No such file or directory\r\n\r\n\r\nFailed to load the native TensorFlow runtime.\r\n\r\nSee https://www.tensorflow.org/install/install_sources#common_installation_problems\r\n\r\nfor some common reasons and solutions.  Include the entire stack trace\r\nabove this error message when asking for help."}